============================= test session starts =============================
platform win32 -- Python 3.13.7, pytest-8.4.1, pluggy-1.6.0 -- C:\Users\Shakour\AppData\Local\Programs\Python\Python313\python.exe
cachedir: .pytest_cache
rootdir: E:\Shakour\MyProjects\AutoProjectManagement\tests
configfile: pytest.ini
plugins: anyio-4.10.0, Faker-37.6.0, cov-6.2.1, mock-3.14.1, xdist-3.8.0
collecting ... collected 0 items / 1 error

=================================== ERRORS ====================================
_ ERROR collecting code_tests/01_UnitTests/main_modules/test_commit_progress_manager.py _
ImportError while importing test module 'E:\Shakour\MyProjects\AutoProjectManagement\tests\code_tests\01_UnitTests\main_modules\test_commit_progress_manager.py'.
Hint: make sure your test modules/packages have valid Python names.
Traceback:
C:\Users\Shakour\AppData\Local\Programs\Python\Python313\Lib\importlib\__init__.py:88: in import_module
    return _bootstrap._gcd_import(name[level:], package, level)
           ^^^^^^^^^^^^^^^^^^^^^^^^^^^^^^^^^^^^^^^^^^^^^^^^^^^^
tests\code_tests\01_UnitTests\main_modules\test_commit_progress_manager.py:12: in <module>
    from autoprojectmanagement.main_modules.quality_commit_management.commit_progress_manager import (
E   ModuleNotFoundError: No module named 'autoprojectmanagement'
=========================== short test summary info ===========================
ERROR tests\code_tests\01_UnitTests\main_modules\test_commit_progress_manager.py
!!!!!!!!!!!!!!!!!!! Interrupted: 1 error during collection !!!!!!!!!!!!!!!!!!!!
============================== 1 error in 0.46s ===============================
